<mujoco model="template">
  <!-- This model has been converted from an OpenSim model. Model conversion by MyoConverter https://github.com/MyoHub/myoConverter. This model is licensed under Apache 2.0. -->
  <!-- Credits from the original OpenSim model. Note! If the following has any license information, it applies to the original OpenSim model. Credits: A planar reduced gait model with 10 degrees of freedom and 18 muscles by Ajay Seth. Closely based on Delp S.L., Loan J.P., Hoy M.G., Zajac F.E., Topp E.L., Rosen J.M., Thelen D.G., Anderson F.C., Seth A. Notes: 3D, 23 DOF gait model created by D.G. Thelen, Univ. of Wisconsin-Madison, and Ajay Seth, Frank C. Anderson, and Scott L. Delp, Stanford University. Lower extremity joint defintions based on Delp et al. (1990). Low back joint and anthropometry based on Anderson and Pandy (1999, 2001). Planar knee model of Yamaguchi and Zajac (1989). Seth replaced tibia translation constraints with a CustomJoint for the knee and removed the patella to eliminate all kinematic constraints; insertions of the quadrucepts are handled with moving points in the tibia frame as defined by Delp 1990. Number of muscles was reduced by Anderson to improve simulation speed for demonstrations and is not intended to be used in research. License: Creative Commons (CCBY 3.0). You are free to distribute, remix, tweak, and build upon this work, even commercially, as long as you credit us for the original creation. http://creativecommons.org/licenses/by/3.0/ More Information: http://simtk-confluence.stanford.edu:8080/display/OpenSim/Gait+2392+and+2354+Models -->
  <!-- Note: inertiagrouprange="0 1" means that groups 0-1 will be used to infer masses/inertias, and groups 2-5 are
  only for visualisation (e.g. wrapping objects) !-->
  <compiler inertiafromgeom="auto" angle="radian" balanceinertia="true" boundmass="0.001" boundinertia="0.001" inertiagrouprange="0 1">
    <lengthrange inttotal="50" useexisting="true"/>
  </compiler>
  <option collision="predefined"/>
  <visual>
    <scale framelength="0.5" framewidth="0.01"/>
  </visual>
  <default>
    <joint limited="true" damping="0.05" armature="0.00001" stiffness="0"/>
    <geom rgba="0.8 0.6 .4 1" margin="0.001"/>
    <site size="0.001"/>
    <tendon width="0.005" rgba=".95 .3 .3 1" limited="false"/>
    <default class="muscle">
      <muscle ctrllimited="true" ctrlrange="0 1" scale="200"/>
    </default>
    <default class="motor">
      <general gainprm="5 0 0 0 0 0 0 0 0 0"/>
    </default>
  </default>
  <option timestep="0.002"/>
  <!-- nuser_jnt=1, the parameter is used to store default value of the joint, and nkey=1 to store keyframe with
   default joint positions set !-->
  <size njmax="1000" nconmax="400" nuser_jnt="1" nkey="1"/>
  <worldbody>
    <!-- The converter script assumes a body named 'ground' exists as a child element of worldbody -->
    <body name="ground" euler="1.571 0 0">
      <geom name="ground-plane" pos="0 0 0" euler="-1.571 0 0" size="10 10 0.125" type="plane" rgba="1.0 0.7 0.4 1.0" condim="3"/>
    </body>
    <light directional="true"/>
    <body name="pelvis" pos="0 0 0" euler="1.571 0 0">
      <inertial mass="11.776999999999999" pos="-0.070699999999999999 0 0" fullinertia="0.1028 0.087099999999999997 0.0579 0 0 0"/>
      <geom name="pelvis_geom_1" type="mesh" mesh="pelvis_geom_1_sacrum" rgba="1 1 1 1" group="0"/>
      <geom name="pelvis_geom_2" type="mesh" mesh="pelvis_geom_2_pelvis" rgba="1 1 1 1" group="0"/>
      <geom name="pelvis_geom_3" type="mesh" mesh="pelvis_geom_3_l_pelvis" rgba="1 1 1 1" group="0"/>
      <joint name="pelvis_tx" range="-5 5" limited="true" user="0.0" ref="0" axis="1 0 0" type="slide" damping="0" stiffness="0"/>
      <joint name="pelvis_ty" range="-1 2" limited="true" user="0.95" ref="0" axis="0 1 0" type="slide" damping="0" stiffness="0"/>
      <joint name="pelvis_tilt" range="-1.571 1.571" limited="true" user="0.0" ref="0" axis="0 0 1" type="hinge" damping="0" stiffness="0"/>
      <body name="femur_r" pos="-0.0707 -0.0661 0.0835" euler="0 0 0">
        <inertial mass="9.3013999999999992" pos="0 -0.17000000000000001 0" fullinertia="0.13389999999999999 0.035099999999999999 0.14119999999999999 0 0 0"/>
        <geom name="femur_r_geom_1" type="mesh" mesh="femur_r_geom_1_femur_r" rgba="1 1 1 1" group="0"/>
        <joint name="hip_flexion_r" range="-2.094 2.094" limited="true" user="0.0" ref="0" type="hinge" axis="0 0 1"/>
        <body name="tibia_r" pos="0 0 0" euler="0 0 0">
          <inertial mass="3.7075" pos="0 -0.1867 0" fullinertia="0.0504 0.0051000000000000004 0.0511 0 0 0"/>
          <geom name="tibia_r_geom_1" type="mesh" mesh="tibia_r_geom_1_tibia_r" rgba="1 1 1 1" group="0"/>
          <geom name="tibia_r_geom_2" type="mesh" mesh="tibia_r_geom_2_fibula" rgba="1 1 1 1" group="0"/>
          <joint name="knee_r_translation1" range="-0.005574 0.00411" limited="true" user="-0.0036392466304026026" ref="0" axis="1 0 0" type="slide"/>
          <joint name="knee_r_translation2" range="-0.4226 -0.3953" limited="true" user="-0.39571344513759116" ref="0" axis="0 1 0" type="slide"/>
          <joint name="knee_angle_r" range="-2.094 0.1745" limited="true" user="0.0" ref="0" axis="0 0 1" type="hinge"/>
          <body name="talus_r" pos="0 -0.43 0" euler="0 0 0">
            <inertial mass="0.10000000000000001" pos="0 0 0" fullinertia="0.001 0.001 0.001 0 0 0"/>
            <geom name="talus_r_geom_1" type="mesh" mesh="talus_r_geom_1_talus" rgba="1 1 1 1" group="0"/>
            <joint name="ankle_angle_r" range="-1.571 1.571" limited="true" user="0.0" ref="0" type="hinge" axis="0 0 1"/>
            <body name="calcn_r" pos="-0.04877 -0.04195 0.00792" euler="0 0 0">
              <inertial mass="1.25" pos="0.10000000000000001 0.029999999999999999 0" fullinertia="0.0014 0.0038999999999999998 0.0041000000000000003 0 0 0"/>
              <geom name="calcn_r_geom_1" type="mesh" mesh="calcn_r_geom_1_foot" rgba="1 1 1 1" group="0"/>
              <body name="toes_r" pos="0.1788 -0.002 0.00108" euler="0 0 0">
                <inertial mass="0.21659999999999999" pos="0.034599999999999999 0.0060000000000000001 -0.017500000000000002" fullinertia="0.0001 0.00020000000000000001 0.0001 0 0 0"/>
                <geom name="toes_r_geom_1" type="mesh" mesh="toes_r_geom_1_bofoot" rgba="1 1 1 1" group="0"/>
              </body>
              <site name="gastroc_r_med_gas_r-P3" pos="0 0.031 -0.0053"/>
              <site name="soleus_r_soleus_r-P2" pos="0 0.031 -0.0053"/>
              <site name="tib_ant_r_tib_ant_r-P3" pos="0.1166 0.0178 -0.030499999999999999"/>
            </body>
          </body>
          <site name="hamstrings_r_bifemlh_r-P2" pos="-0.030099999999999998 -0.035999999999999997 0.029430000000000001"/>
          <site name="hamstrings_r_bifemlh_r-P3" pos="-0.023400000000000001 -0.056300000000000003 0.034299999999999997"/>
          <site name="bifemsh_r_bifemsh_r-P2" pos="-0.030099999999999998 -0.035999999999999997 0.029430000000000001"/>
          <site name="bifemsh_r_bifemsh_r-P3" pos="-0.023400000000000001 -0.056300000000000003 0.034299999999999997"/>
          <body name="rect_fem_r_rect_fem_r-P3" pos="0 0 0.001399">
            <geom size="0.0005 0.0005 0.0005" rgba="0.0 0.0 1.0 0.0" contype="2" conaffinity="2"/>
            <joint name="rect_fem_r_rect_fem_r-P3_x" type="slide" axis="1 0 0" range="0.01558 0.0733"/>
            <joint name="rect_fem_r_rect_fem_r-P3_y" type="slide" axis="0 1 0" range="-0.06738 0.02531"/>
            <site name="rect_fem_r_rect_fem_r-P3"/>
          </body>
          <body name="vasti_r_vas_int_r-P4" pos="0 0 0.001799">
            <geom size="0.0005 0.0005 0.0005" rgba="0.0 0.0 1.0 0.0" contype="2" conaffinity="2"/>
            <joint name="vasti_r_vas_int_r-P4_x" type="slide" axis="1 0 0" range="0.008273 0.06844"/>
            <joint name="vasti_r_vas_int_r-P4_y" type="slide" axis="0 1 0" range="-0.06857 0.02752"/>
            <site name="vasti_r_vas_int_r-P4"/>
          </body>
          <site name="soleus_r_soleus_r-P1" pos="-0.0023999999999999998 -0.15329999999999999 0.0071000000000000004"/>
          <site name="tib_ant_r_tib_ant_r-P1" pos="0.017899999999999999 -0.16239999999999999 0.0115"/>
          <site name="tib_ant_r_tib_ant_r-P2" pos="0.032899999999999999 -0.39510000000000001 -0.0177"/>
        </body>
        <site name="bifemsh_r_bifemsh_r-P1" pos="0.0050000000000000001 -0.21110000000000001 0.023400000000000001"/>
        <site name="glut_max_r_glut_max_r-P3" pos="-0.042599999999999999 -0.052999999999999999 0.0293"/>
        <site name="glut_max_r_glut_max_r-P4" pos="-0.015599999999999999 -0.1016 0.0419"/>
        <site name="iliopsoas_r_psoas_r-P4" pos="0.0016000000000000001 -0.050700000000000002 0.0038"/>
        <site name="iliopsoas_r_psoas_r-P5" pos="-0.018800000000000001 -0.059700000000000003 0.0104"/>
        <site name="rect_fem_r_rect_fem_r-P2" pos="0.033399999999999999 -0.40300000000000002 0.0019"/>
        <site name="vasti_r_vas_int_r-P1" pos="0.029000000000000001 -0.19239999999999999 0.031"/>
        <site name="vasti_r_vas_int_r-P2" pos="0.033500000000000002 -0.2084 0.028500000000000001"/>
        <body name="vasti_r_vas_int_r-P3" pos="0.0335 0 0">
          <geom size="0.0005 0.0005 0.0005" rgba="0.0 0.0 1.0 0.0" contype="2" conaffinity="2"/>
          <joint name="vasti_r_vas_int_r-P3_y" type="slide" axis="0 1 0" range="-0.403 -0.2084"/>
          <joint name="vasti_r_vas_int_r-P3_z" type="slide" axis="0 0 1" range="0.0055 0.0285"/>
          <site name="vasti_r_vas_int_r-P3"/>
        </body>
        <site name="gastroc_r_med_gas_r-P1" pos="-0.019 -0.39290000000000003 -0.0235"/>
        <body name="gastroc_r_med_gas_r-P2" pos="0 0 0">
          <geom size="0.0005 0.0005 0.0005" rgba="0.0 0.0 1.0 0.0" contype="2" conaffinity="2"/>
          <joint name="gastroc_r_med_gas_r-P2_x" type="slide" axis="1 0 0" range="-0.03 -0.019"/>
          <joint name="gastroc_r_med_gas_r-P2_y" type="slide" axis="0 1 0" range="-0.4022 -0.3929"/>
          <joint name="gastroc_r_med_gas_r-P2_z" type="slide" axis="0 0 1" range="-0.0258 -0.0235"/>
          <site name="gastroc_r_med_gas_r-P2"/>
        </body>
      </body>
      <body name="femur_l" pos="-0.0707 -0.0661 -0.0835" euler="0 0 0">
        <inertial mass="9.3013999999999992" pos="0 -0.17000000000000001 0" fullinertia="0.13389999999999999 0.035099999999999999 0.14119999999999999 0 0 0"/>
        <geom name="femur_l_geom_1" type="mesh" mesh="femur_l_geom_1_femur_l" rgba="1 1 1 1" group="0"/>
        <joint name="hip_flexion_l" range="-2.094 2.094" limited="true" user="0.0" ref="0" type="hinge" axis="0 0 1"/>
        <body name="tibia_l" pos="0 0 0" euler="0 0 0">
          <inertial mass="3.7075" pos="0 -0.1867 0" fullinertia="0.0504 0.0051000000000000004 0.0511 0 0 0"/>
          <geom name="tibia_l_geom_1" type="mesh" mesh="tibia_l_geom_1_tibia_l" rgba="1 1 1 1" group="0"/>
          <geom name="tibia_l_geom_2" type="mesh" mesh="tibia_l_geom_2_l_fibula" rgba="1 1 1 1" group="0"/>
          <joint name="knee_l_translation1" range="-0.005574 0.00411" limited="true" user="-0.0036392466304026026" ref="0" axis="1 0 0" type="slide"/>
          <joint name="knee_l_translation2" range="-0.4226 -0.3953" limited="true" user="-0.39571344513759116" ref="0" axis="0 1 0" type="slide"/>
          <joint name="knee_angle_l" range="-2.094 0.1745" limited="true" user="0.0" ref="0" axis="0 0 1" type="hinge"/>
          <body name="talus_l" pos="0 -0.43 0" euler="0 0 0">
            <inertial mass="0.10000000000000001" pos="0 0 0" fullinertia="0.001 0.001 0.001 0 0 0"/>
            <geom name="talus_l_geom_1" type="mesh" mesh="talus_l_geom_1_l_talus" rgba="1 1 1 1" group="0"/>
            <joint name="ankle_angle_l" range="-1.571 1.571" limited="true" user="0.0" ref="0" type="hinge" axis="0 0 1"/>
            <body name="calcn_l" pos="-0.04877 -0.04195 -0.00792" euler="0 0 0">
              <inertial mass="1.25" pos="0.10000000000000001 0.029999999999999999 0" fullinertia="0.0014 0.0038999999999999998 0.0041000000000000003 0 0 0"/>
              <geom name="calcn_l_geom_1" type="mesh" mesh="calcn_l_geom_1_l_foot" rgba="1 1 1 1" group="0"/>
              <body name="toes_l" pos="0.1788 -0.002 -0.00108" euler="0 0 0">
                <inertial mass="0.21659999999999999" pos="0.034599999999999999 0.0060000000000000001 0.017500000000000002" fullinertia="0.0001 0.00020000000000000001 0.0001 0 0 0"/>
                <geom name="toes_l_geom_1" type="mesh" mesh="toes_l_geom_1_l_bofoot" rgba="1 1 1 1" group="0"/>
              </body>
              <site name="gastroc_l_med_gas_l-P3" pos="0 0.031 0.0053"/>
              <site name="soleus_l_soleus_l-P2" pos="0 0.031 0.0053"/>
              <site name="tib_ant_l_tib_ant_l-P3" pos="0.1166 0.0178 0.030499999999999999"/>
            </body>
          </body>
          <site name="hamstrings_l_bifemlh_l-P2" pos="-0.030099999999999998 -0.035999999999999997 -0.029430000000000001"/>
          <site name="hamstrings_l_bifemlh_l-P3" pos="-0.023400000000000001 -0.056300000000000003 -0.034299999999999997"/>
          <site name="bifemsh_l_bifemsh_l-P2" pos="-0.030099999999999998 -0.035999999999999997 -0.029430000000000001"/>
          <site name="bifemsh_l_bifemsh_l-P3" pos="-0.023400000000000001 -0.056300000000000003 -0.034299999999999997"/>
          <body name="rect_fem_l_rect_fem_l-P3" pos="0 0 -0.001401">
            <geom size="0.0005 0.0005 0.0005" rgba="0.0 0.0 1.0 0.0" contype="2" conaffinity="2"/>
            <joint name="rect_fem_l_rect_fem_l-P3_x" type="slide" axis="1 0 0" range="0.01558 0.0733"/>
            <joint name="rect_fem_l_rect_fem_l-P3_y" type="slide" axis="0 1 0" range="-0.06738 0.02531"/>
            <site name="rect_fem_l_rect_fem_l-P3"/>
          </body>
          <body name="vasti_l_vas_int_l-P4" pos="0 0 -0.001801">
            <geom size="0.0005 0.0005 0.0005" rgba="0.0 0.0 1.0 0.0" contype="2" conaffinity="2"/>
            <joint name="vasti_l_vas_int_l-P4_x" type="slide" axis="1 0 0" range="0.008273 0.06844"/>
            <joint name="vasti_l_vas_int_l-P4_y" type="slide" axis="0 1 0" range="-0.06857 0.02752"/>
            <site name="vasti_l_vas_int_l-P4"/>
          </body>
          <site name="soleus_l_soleus_l-P1" pos="-0.0023999999999999998 -0.15329999999999999 -0.0071000000000000004"/>
          <site name="tib_ant_l_tib_ant_l-P1" pos="0.017899999999999999 -0.16239999999999999 -0.0115"/>
          <site name="tib_ant_l_tib_ant_l-P2" pos="0.032899999999999999 -0.39510000000000001 0.0177"/>
        </body>
        <site name="bifemsh_l_bifemsh_l-P1" pos="0.0050000000000000001 -0.21110000000000001 -0.023400000000000001"/>
        <site name="glut_max_l_glut_max_l-P3" pos="-0.042599999999999999 -0.052999999999999999 -0.0293"/>
        <site name="glut_max_l_glut_max_l-P4" pos="-0.015599999999999999 -0.1016 -0.0419"/>
        <site name="iliopsoas_l_psoas_l-P4" pos="0.0016000000000000001 -0.050700000000000002 -0.0038"/>
        <site name="iliopsoas_l_psoas_l-P5" pos="-0.018800000000000001 -0.059700000000000003 -0.0104"/>
        <site name="rect_fem_l_rect_fem_l-P2" pos="0.033399999999999999 -0.40300000000000002 -0.0019"/>
        <site name="vasti_l_vas_int_l-P1" pos="0.029000000000000001 -0.19239999999999999 -0.031"/>
        <site name="vasti_l_vas_int_l-P2" pos="0.033500000000000002 -0.2084 -0.028500000000000001"/>
        <body name="vasti_l_vas_int_l-P3" pos="0.0335 0 0">
          <geom size="0.0005 0.0005 0.0005" rgba="0.0 0.0 1.0 0.0" contype="2" conaffinity="2"/>
          <joint name="vasti_l_vas_int_l-P3_y" type="slide" axis="0 1 0" range="-0.403 -0.2084"/>
          <joint name="vasti_l_vas_int_l-P3_z" type="slide" axis="0 0 1" range="-0.0285 -0.0055"/>
          <site name="vasti_l_vas_int_l-P3"/>
        </body>
        <site name="gastroc_l_med_gas_l-P1" pos="-0.019 -0.39290000000000003 0.0235"/>
        <body name="gastroc_l_med_gas_l-P2" pos="0 0 0">
          <geom size="0.0005 0.0005 0.0005" rgba="0.0 0.0 1.0 0.0" contype="2" conaffinity="2"/>
          <joint name="gastroc_l_med_gas_l-P2_x" type="slide" axis="1 0 0" range="-0.03 -0.019"/>
          <joint name="gastroc_l_med_gas_l-P2_y" type="slide" axis="0 1 0" range="-0.4022 -0.3929"/>
          <joint name="gastroc_l_med_gas_l-P2_z" type="slide" axis="0 0 1" range="0.0235 0.0258"/>
          <site name="gastroc_l_med_gas_l-P2"/>
        </body>
      </body>
      <body name="torso" pos="-0.1007 0.0815 0" euler="0 0 0">
        <inertial mass="34.236600000000003" pos="-0.029999999999999999 0.32000000000000001 0" fullinertia="1.4744999999999999 0.75549999999999995 1.4314 0 0 0"/>
        <geom name="torso_geom_1" type="mesh" mesh="torso_geom_1_hat_spine" rgba="1 1 1 1" group="0"/>
        <geom name="torso_geom_2" type="mesh" mesh="torso_geom_2_hat_jaw" rgba="1 1 1 1" group="0"/>
        <geom name="torso_geom_3" type="mesh" mesh="torso_geom_3_hat_skull" rgba="1 1 1 1" group="0"/>
        <geom name="torso_geom_4" type="mesh" mesh="torso_geom_4_hat_ribs" rgba="1 1 1 1" group="0"/>
        <joint name="lumbar_extension" range="-1.571 1.571" limited="true" user="0.0" ref="0" type="hinge" axis="0 0 1"/>
      </body>
      <site name="hamstrings_r_bifemlh_r-P1" pos="-0.12595999999999999 -0.10256999999999999 0.069440000000000002"/>
      <site name="glut_max_r_glut_max_r-P1" pos="-0.13489999999999999 0.017600000000000001 0.056300000000000003"/>
      <site name="glut_max_r_glut_max_r-P2" pos="-0.1376 -0.051999999999999998 0.091399999999999995"/>
      <site name="iliopsoas_r_psoas_r-P1" pos="-0.064699999999999994 0.088700000000000001 0.028899999999999999"/>
      <site name="iliopsoas_r_psoas_r-P2" pos="-0.023800000000000002 -0.057000000000000002 0.075899999999999995"/>
      <body name="iliopsoas_r_psoas_r-P3" pos="0 0 0">
        <geom size="0.0005 0.0005 0.0005" rgba="0.0 0.0 1.0 0.0" contype="2" conaffinity="2"/>
        <joint name="iliopsoas_r_psoas_r-P3_x" type="slide" axis="1 0 0" range="-0.0288 -0.0238"/>
        <joint name="iliopsoas_r_psoas_r-P3_y" type="slide" axis="0 1 0" range="-0.0805 -0.057"/>
        <joint name="iliopsoas_r_psoas_r-P3_z" type="slide" axis="0 0 1" range="0.0759 0.0816"/>
        <site name="iliopsoas_r_psoas_r-P3"/>
      </body>
      <site name="rect_fem_r_rect_fem_r-P1" pos="-0.029499999999999998 -0.031099999999999999 0.096799999999999997"/>
      <site name="hamstrings_l_bifemlh_l-P1" pos="-0.12595999999999999 -0.10256999999999999 -0.069440000000000002"/>
      <site name="glut_max_l_glut_max_l-P1" pos="-0.13489999999999999 0.017600000000000001 -0.056300000000000003"/>
      <site name="glut_max_l_glut_max_l-P2" pos="-0.1376 -0.051999999999999998 -0.091399999999999995"/>
      <site name="iliopsoas_l_psoas_l-P1" pos="-0.064699999999999994 0.088700000000000001 -0.028899999999999999"/>
      <site name="iliopsoas_l_psoas_l-P2" pos="-0.023800000000000002 -0.057000000000000002 -0.075899999999999995"/>
      <body name="iliopsoas_l_psoas_l-P3" pos="0 0 0">
        <geom size="0.0005 0.0005 0.0005" rgba="0.0 0.0 1.0 0.0" contype="2" conaffinity="2"/>
        <joint name="iliopsoas_l_psoas_l-P3_x" type="slide" axis="1 0 0" range="-0.0288 -0.0238"/>
        <joint name="iliopsoas_l_psoas_l-P3_y" type="slide" axis="0 1 0" range="-0.0805 -0.057"/>
        <joint name="iliopsoas_l_psoas_l-P3_z" type="slide" axis="0 0 1" range="-0.0816 -0.0759"/>
        <site name="iliopsoas_l_psoas_l-P3"/>
      </body>
      <site name="rect_fem_l_rect_fem_l-P1" pos="-0.029499999999999998 -0.031099999999999999 -0.096799999999999997"/>
    </body>
  </worldbody>
  <asset>
    <texture type="skybox" builtin="gradient" rgb1="1 1 1" rgb2="0.6 0.8 1" width="256" height="256"/>
    <mesh name="pelvis_geom_1_sacrum" file="Geometry/sacrum.stl" scale="1 1 1"/>
    <mesh name="pelvis_geom_2_pelvis" file="Geometry/pelvis.stl" scale="1 1 1"/>
    <mesh name="pelvis_geom_3_l_pelvis" file="Geometry/l_pelvis.stl" scale="1 1 1"/>
    <mesh name="femur_r_geom_1_femur_r" file="Geometry/femur_r.stl" scale="1 1 1"/>
    <mesh name="tibia_r_geom_1_tibia_r" file="Geometry/tibia_r.stl" scale="1 1 1"/>
    <mesh name="tibia_r_geom_2_fibula" file="Geometry/fibula.stl" scale="1 1 1"/>
    <mesh name="talus_r_geom_1_talus" file="Geometry/talus.stl" scale="1 1 1"/>
    <mesh name="calcn_r_geom_1_foot" file="Geometry/foot.stl" scale="1 1 1"/>
    <mesh name="toes_r_geom_1_bofoot" file="Geometry/bofoot.stl" scale="1 1 1"/>
    <mesh name="femur_l_geom_1_femur_l" file="Geometry/femur_l.stl" scale="1 1 1"/>
    <mesh name="tibia_l_geom_1_tibia_l" file="Geometry/tibia_l.stl" scale="1 1 1"/>
    <mesh name="tibia_l_geom_2_l_fibula" file="Geometry/l_fibula.stl" scale="1 1 1"/>
    <mesh name="talus_l_geom_1_l_talus" file="Geometry/l_talus.stl" scale="1 1 1"/>
    <mesh name="calcn_l_geom_1_l_foot" file="Geometry/l_foot.stl" scale="1 1 1"/>
    <mesh name="toes_l_geom_1_l_bofoot" file="Geometry/l_bofoot.stl" scale="1 1 1"/>
    <mesh name="torso_geom_1_hat_spine" file="Geometry/hat_spine.stl" scale="1 1 1"/>
    <mesh name="torso_geom_2_hat_jaw" file="Geometry/hat_jaw.stl" scale="1 1 1"/>
    <mesh name="torso_geom_3_hat_skull" file="Geometry/hat_skull.stl" scale="1 1 1"/>
    <mesh name="torso_geom_4_hat_ribs" file="Geometry/hat_ribs.stl" scale="1 1 1"/>
  </asset>
  <tendon>
    <!-- Leave this comment here to make 'tendon' element pretty printed !-->
    <spatial name="hamstrings_r_tendon">
      <site site="hamstrings_r_bifemlh_r-P1"/>
      <site site="hamstrings_r_bifemlh_r-P2"/>
      <site site="hamstrings_r_bifemlh_r-P3"/>
    </spatial>
    <spatial name="bifemsh_r_tendon">
      <site site="bifemsh_r_bifemsh_r-P1"/>
      <site site="bifemsh_r_bifemsh_r-P2"/>
      <site site="bifemsh_r_bifemsh_r-P3"/>
    </spatial>
    <spatial name="glut_max_r_tendon">
      <site site="glut_max_r_glut_max_r-P1"/>
      <site site="glut_max_r_glut_max_r-P2"/>
      <site site="glut_max_r_glut_max_r-P3"/>
      <site site="glut_max_r_glut_max_r-P4"/>
    </spatial>
    <spatial name="iliopsoas_r_tendon">
      <site site="iliopsoas_r_psoas_r-P1"/>
      <site site="iliopsoas_r_psoas_r-P2"/>
      <site site="iliopsoas_r_psoas_r-P3"/>
      <site site="iliopsoas_r_psoas_r-P4"/>
      <site site="iliopsoas_r_psoas_r-P5"/>
    </spatial>
    <spatial name="rect_fem_r_tendon">
      <site site="rect_fem_r_rect_fem_r-P1"/>
      <site site="rect_fem_r_rect_fem_r-P2"/>
      <site site="rect_fem_r_rect_fem_r-P3"/>
    </spatial>
    <spatial name="vasti_r_tendon">
      <site site="vasti_r_vas_int_r-P1"/>
      <site site="vasti_r_vas_int_r-P2"/>
      <site site="vasti_r_vas_int_r-P3"/>
      <site site="vasti_r_vas_int_r-P4"/>
    </spatial>
    <spatial name="gastroc_r_tendon">
      <site site="gastroc_r_med_gas_r-P1"/>
      <site site="gastroc_r_med_gas_r-P2"/>
      <site site="gastroc_r_med_gas_r-P3"/>
    </spatial>
    <spatial name="soleus_r_tendon">
      <site site="soleus_r_soleus_r-P1"/>
      <site site="soleus_r_soleus_r-P2"/>
    </spatial>
    <spatial name="tib_ant_r_tendon">
      <site site="tib_ant_r_tib_ant_r-P1"/>
      <site site="tib_ant_r_tib_ant_r-P2"/>
      <site site="tib_ant_r_tib_ant_r-P3"/>
    </spatial>
    <spatial name="hamstrings_l_tendon">
      <site site="hamstrings_l_bifemlh_l-P1"/>
      <site site="hamstrings_l_bifemlh_l-P2"/>
      <site site="hamstrings_l_bifemlh_l-P3"/>
    </spatial>
    <spatial name="bifemsh_l_tendon">
      <site site="bifemsh_l_bifemsh_l-P1"/>
      <site site="bifemsh_l_bifemsh_l-P2"/>
      <site site="bifemsh_l_bifemsh_l-P3"/>
    </spatial>
    <spatial name="glut_max_l_tendon">
      <site site="glut_max_l_glut_max_l-P1"/>
      <site site="glut_max_l_glut_max_l-P2"/>
      <site site="glut_max_l_glut_max_l-P3"/>
      <site site="glut_max_l_glut_max_l-P4"/>
    </spatial>
    <spatial name="iliopsoas_l_tendon">
      <site site="iliopsoas_l_psoas_l-P1"/>
      <site site="iliopsoas_l_psoas_l-P2"/>
      <site site="iliopsoas_l_psoas_l-P3"/>
      <site site="iliopsoas_l_psoas_l-P4"/>
      <site site="iliopsoas_l_psoas_l-P5"/>
    </spatial>
    <spatial name="rect_fem_l_tendon">
      <site site="rect_fem_l_rect_fem_l-P1"/>
      <site site="rect_fem_l_rect_fem_l-P2"/>
      <site site="rect_fem_l_rect_fem_l-P3"/>
    </spatial>
    <spatial name="vasti_l_tendon">
      <site site="vasti_l_vas_int_l-P1"/>
      <site site="vasti_l_vas_int_l-P2"/>
      <site site="vasti_l_vas_int_l-P3"/>
      <site site="vasti_l_vas_int_l-P4"/>
    </spatial>
    <spatial name="gastroc_l_tendon">
      <site site="gastroc_l_med_gas_l-P1"/>
      <site site="gastroc_l_med_gas_l-P2"/>
      <site site="gastroc_l_med_gas_l-P3"/>
    </spatial>
    <spatial name="soleus_l_tendon">
      <site site="soleus_l_soleus_l-P1"/>
      <site site="soleus_l_soleus_l-P2"/>
    </spatial>
    <spatial name="tib_ant_l_tendon">
      <site site="tib_ant_l_tib_ant_l-P1"/>
      <site site="tib_ant_l_tib_ant_l-P2"/>
      <site site="tib_ant_l_tib_ant_l-P3"/>
    </spatial>
  </tendon>
  <actuator>
    <!-- Leave this comment here to make 'actuator' element pretty printed !-->
    <muscle name="hamstrings_r" lengthrange="0.01 1" force="2700" tendon="hamstrings_r_tendon" class="muscle" timeconst="0.01 0.04"/>
    <muscle name="bifemsh_r" lengthrange="0.01 1" force="804" tendon="bifemsh_r_tendon" class="muscle" timeconst="0.01 0.04"/>
    <muscle name="glut_max_r" lengthrange="0.01 1" force="1944" tendon="glut_max_r_tendon" class="muscle" timeconst="0.01 0.04"/>
    <muscle name="iliopsoas_r" lengthrange="0.01 1" force="2342" tendon="iliopsoas_r_tendon" class="muscle" timeconst="0.01 0.04"/>
    <muscle name="rect_fem_r" lengthrange="0.01 1" force="1169" tendon="rect_fem_r_tendon" class="muscle" timeconst="0.01 0.04"/>
    <muscle name="vasti_r" lengthrange="0.01 1" force="5000" tendon="vasti_r_tendon" class="muscle" timeconst="0.01 0.04"/>
    <muscle name="gastroc_r" lengthrange="0.01 1" force="2500" tendon="gastroc_r_tendon" class="muscle" timeconst="0.01 0.04"/>
    <muscle name="soleus_r" lengthrange="0.01 1" force="5137" tendon="soleus_r_tendon" class="muscle" timeconst="0.01 0.04"/>
    <muscle name="tib_ant_r" lengthrange="0.01 1" force="3000" tendon="tib_ant_r_tendon" class="muscle" timeconst="0.01 0.04"/>
    <muscle name="hamstrings_l" lengthrange="0.01 1" force="2700" tendon="hamstrings_l_tendon" class="muscle" timeconst="0.01 0.04"/>
    <muscle name="bifemsh_l" lengthrange="0.01 1" force="804" tendon="bifemsh_l_tendon" class="muscle" timeconst="0.01 0.04"/>
    <muscle name="glut_max_l" lengthrange="0.01 1" force="1944" tendon="glut_max_l_tendon" class="muscle" timeconst="0.01 0.04"/>
    <muscle name="iliopsoas_l" lengthrange="0.01 1" force="2342" tendon="iliopsoas_l_tendon" class="muscle" timeconst="0.01 0.04"/>
    <muscle name="rect_fem_l" lengthrange="0.01 1" force="1169" tendon="rect_fem_l_tendon" class="muscle" timeconst="0.01 0.04"/>
    <muscle name="vasti_l" lengthrange="0.01 1" force="5000" tendon="vasti_l_tendon" class="muscle" timeconst="0.01 0.04"/>
    <muscle name="gastroc_l" lengthrange="0.01 1" force="2500" tendon="gastroc_l_tendon" class="muscle" timeconst="0.01 0.04"/>
    <muscle name="soleus_l" lengthrange="0.01 1" force="5137" tendon="soleus_l_tendon" class="muscle" timeconst="0.01 0.04"/>
    <muscle name="tib_ant_l" lengthrange="0.01 1" force="3000" tendon="tib_ant_l_tendon" class="muscle" timeconst="0.01 0.04"/>
  </actuator>
  <equality>
    <!-- Leave this comment here to make 'equality' element pretty printed !-->
    <joint joint1="knee_r_translation1" joint2="knee_angle_r" polycoef="-0.003639 -0.006267 0.002807 0.00134 -0.0006776" solimp="0.9999 0.9999 0.001 0.5 2" active="true"/>
    <joint joint1="knee_r_translation2" joint2="knee_angle_r" polycoef="-0.3957 0.003413 -0.005587 0.0006697 0.0005674" solimp="0.9999 0.9999 0.001 0.5 2" active="true"/>
    <joint joint1="knee_l_translation1" joint2="knee_angle_l" polycoef="-0.003639 -0.006267 0.002807 0.00134 -0.0006776" solimp="0.9999 0.9999 0.001 0.5 2" active="true"/>
    <joint joint1="knee_l_translation2" joint2="knee_angle_l" polycoef="-0.3957 0.003413 -0.005587 0.0006697 0.0005674" solimp="0.9999 0.9999 0.001 0.5 2" active="true"/>
    <joint joint1="iliopsoas_r_psoas_r-P3_x" joint2="hip_flexion_r" polycoef="-0.0288 3.166e-18 0.00114 0 0" solimp="0.9999 0.9999 0.001 0.5 2"/>
    <joint joint1="iliopsoas_r_psoas_r-P3_y" joint2="hip_flexion_r" polycoef="-0.0805 4.835e-18 0.005359 0 0" solimp="0.9999 0.9999 0.001 0.5 2"/>
    <joint joint1="iliopsoas_r_psoas_r-P3_z" joint2="hip_flexion_r" polycoef="0.0816 -4.705e-18 -0.0013 0 0" solimp="0.9999 0.9999 0.001 0.5 2"/>
    <joint joint1="rect_fem_r_rect_fem_r-P3_x" joint2="knee_angle_r" polycoef="0.06259 0.04199 0.01152 -0.007248 -0.004008" solimp="0.9999 0.9999 0.001 0.5 2"/>
    <joint joint1="rect_fem_r_rect_fem_r-P3_y" joint2="knee_angle_r" polycoef="0.02032 -0.01159 -0.008624 -0.002308 -0.0002292" solimp="0.9999 0.9999 0.001 0.5 2"/>
    <joint joint1="vasti_r_vas_int_r-P3_y" joint2="knee_angle_r" polycoef="-0.2234 0.08578 0 0 0" solimp="0.9999 0.9999 0.001 0.5 2"/>
    <joint joint1="vasti_r_vas_int_r-P3_z" joint2="knee_angle_r" polycoef="0.02673 0.01014 0 0 0" solimp="0.9999 0.9999 0.001 0.5 2"/>
    <joint joint1="vasti_r_vas_int_r-P4_x" joint2="knee_angle_r" polycoef="0.05647 0.04555 0.01393 -0.007247 -0.004235" solimp="0.9999 0.9999 0.001 0.5 2"/>
    <joint joint1="vasti_r_vas_int_r-P4_y" joint2="knee_angle_r" polycoef="0.02476 -0.006322 -0.00661 -0.003684 -0.0008973" solimp="0.9999 0.9999 0.001 0.5 2"/>
    <joint joint1="gastroc_r_med_gas_r-P2_x" joint2="knee_angle_r" polycoef="-0.02915 -0.004849 0 0 0" solimp="0.9999 0.9999 0.001 0.5 2"/>
    <joint joint1="gastroc_r_med_gas_r-P2_y" joint2="knee_angle_r" polycoef="-0.4015 -0.0041 0 0 0" solimp="0.9999 0.9999 0.001 0.5 2"/>
    <joint joint1="gastroc_r_med_gas_r-P2_z" joint2="knee_angle_r" polycoef="-0.02562 -0.001014 0 0 0" solimp="0.9999 0.9999 0.001 0.5 2"/>
    <joint joint1="iliopsoas_l_psoas_l-P3_x" joint2="hip_flexion_l" polycoef="-0.0288 3.166e-18 0.00114 0 0" solimp="0.9999 0.9999 0.001 0.5 2"/>
    <joint joint1="iliopsoas_l_psoas_l-P3_y" joint2="hip_flexion_l" polycoef="-0.0805 4.835e-18 0.005359 0 0" solimp="0.9999 0.9999 0.001 0.5 2"/>
    <joint joint1="iliopsoas_l_psoas_l-P3_z" joint2="hip_flexion_l" polycoef="-0.0816 4.705e-18 0.0013 0 0" solimp="0.9999 0.9999 0.001 0.5 2"/>
    <joint joint1="rect_fem_l_rect_fem_l-P3_x" joint2="knee_angle_l" polycoef="0.06259 0.04199 0.01152 -0.007248 -0.004008" solimp="0.9999 0.9999 0.001 0.5 2"/>
    <joint joint1="rect_fem_l_rect_fem_l-P3_y" joint2="knee_angle_l" polycoef="0.02032 -0.01159 -0.008624 -0.002308 -0.0002292" solimp="0.9999 0.9999 0.001 0.5 2"/>
    <joint joint1="vasti_l_vas_int_l-P3_y" joint2="knee_angle_l" polycoef="-0.2234 0.08578 0 0 0" solimp="0.9999 0.9999 0.001 0.5 2"/>
    <joint joint1="vasti_l_vas_int_l-P3_z" joint2="knee_angle_l" polycoef="-0.02673 -0.01014 0 0 0" solimp="0.9999 0.9999 0.001 0.5 2"/>
    <joint joint1="vasti_l_vas_int_l-P4_x" joint2="knee_angle_l" polycoef="0.05647 0.04555 0.01393 -0.007247 -0.004235" solimp="0.9999 0.9999 0.001 0.5 2"/>
    <joint joint1="vasti_l_vas_int_l-P4_y" joint2="knee_angle_l" polycoef="0.02476 -0.006322 -0.00661 -0.003684 -0.0008973" solimp="0.9999 0.9999 0.001 0.5 2"/>
    <joint joint1="gastroc_l_med_gas_l-P2_x" joint2="knee_angle_l" polycoef="-0.02915 -0.004849 0 0 0" solimp="0.9999 0.9999 0.001 0.5 2"/>
    <joint joint1="gastroc_l_med_gas_l-P2_y" joint2="knee_angle_l" polycoef="-0.4015 -0.0041 0 0 0" solimp="0.9999 0.9999 0.001 0.5 2"/>
    <joint joint1="gastroc_l_med_gas_l-P2_z" joint2="knee_angle_l" polycoef="0.02562 0.001014 0 0 0" solimp="0.9999 0.9999 0.001 0.5 2"/>
  </equality>
  <contact>
    <!-- Leave this comment here to make 'contact' element pretty printed !-->
    <pair geom1="ground-plane" geom2="pelvis_geom_1"/>
    <pair geom1="ground-plane" geom2="pelvis_geom_2"/>
    <pair geom1="ground-plane" geom2="pelvis_geom_3"/>
    <pair geom1="ground-plane" geom2="femur_r_geom_1"/>
    <pair geom1="ground-plane" geom2="tibia_r_geom_1"/>
    <pair geom1="ground-plane" geom2="tibia_r_geom_2"/>
    <pair geom1="ground-plane" geom2="talus_r_geom_1"/>
    <pair geom1="ground-plane" geom2="calcn_r_geom_1"/>
    <pair geom1="ground-plane" geom2="toes_r_geom_1"/>
    <pair geom1="ground-plane" geom2="femur_l_geom_1"/>
    <pair geom1="ground-plane" geom2="tibia_l_geom_1"/>
    <pair geom1="ground-plane" geom2="tibia_l_geom_2"/>
    <pair geom1="ground-plane" geom2="talus_l_geom_1"/>
    <pair geom1="ground-plane" geom2="calcn_l_geom_1"/>
    <pair geom1="ground-plane" geom2="toes_l_geom_1"/>
    <pair geom1="ground-plane" geom2="torso_geom_1"/>
    <pair geom1="ground-plane" geom2="torso_geom_2"/>
    <pair geom1="ground-plane" geom2="torso_geom_3"/>
    <pair geom1="ground-plane" geom2="torso_geom_4"/>
  </contact>
  <keyframe>
    <key name="default-pose" qpos="0 0.95 0 0 -0.003639 -0.3957 0 0 0.06259 0.02032 0.05647 0.02476 -0.2234 0.02673 -0.02915 -0.4015 -0.02562 0 -0.003639 -0.3957 0 0 0.06259 0.02032 0.05647 0.02476 -0.2234 -0.02673 -0.02915 -0.4015 0.02562 0 -0.0288 -0.0805 0.0816 -0.0288 -0.0805 -0.0816"/>
  </keyframe>
</mujoco>
